<sdf version="1.7">
  <world name="default">
    <gravity>0 0 -9.8 </gravity>

  
  <model name="basic_table_little_dog">
    <pose>0 0 1 0 0 0</pose>
    <link name="top">
      <pose>0 0 0 0 0 0</pose>
        <inertial>
          <mass>20.0</mass>
          <inertia>
            <ixx>0.005833</ixx>
            <ixy>0.0</ixy>
            <ixz>0.0</ixz>
            <iyy>0.005833</iyy>
            <iyz>0.0</iyz>
            <izz>0.005</izz>
          </inertia>
        </inertial>
        <collision name="collision">
          <geometry>
            <box>
              <size>.60 1.0 .1</size>
            </box>
          </geometry>

        </collision>
        <visual name="visual">
          <geometry>
            <box>
              <size>.6 1.0 .1</size>
            </box>
          </geometry>
          <material>
            <diffuse>1.0 1.0 1.0 1.0</diffuse>
          </material>
        </visual>
    </link>
        <link name="lf_leg">
          <pose>0 0 0 0 0 0</pose>
            <inertial>
              <mass>1.0</mass>
              <inertia>
                <ixx>0.005833</ixx>
                <ixy>0.0</ixy>
                <ixz>0.0</ixz>
                <iyy>0.005833</iyy>
                <iyz>0.0</iyz>
                <izz>0.005</izz>
              </inertia>
            </inertial>
            <collision name="collision">
              <geometry>
                <box>
                  <size>.05 .05 .5</size>
                </box>
              </geometry>
            </collision>
            <visual name="visual">
            
              <geometry>
                <box>
                  <size>.05 .05 .5</size>
                </box>
              </geometry>
              <material>
                <diffuse>1.0 1.0 1.0 1.0</diffuse>
              </material>
            </visual>
      </link>


    
    <joint name="lf_joint" type="revolute">
      <parent>top</parent>
      <child>lf_leg</child>
      
      <axis>
        <xyz>1 0 0</xyz>
        <limit>
          <lower>-2</lower>
          <upper>2</upper>
        </limit>
      </axis>
        <pose relative_to="top">
        0 0 -3 0 0 0
      </pose>

      
    </joint>




  </model>
  </world>



</sdf>
